<?xml version="1.0"?>
<robot xmlns:xacro="http://ros.org/wiki/xacro" name="taticoma">

	<xacro:property name="pi" value="3.1415926535897931" />

	<xacro:property name="dim_scale" value="0.001" />

	<!-- <xacro:property name="joint_lower_limit" value="-1.57" />
	<xacro:property name="joint_upper_limit" value="1.57" /> -->

	<xacro:property name="joint_lower_limit" value="-1.657" />
	<xacro:property name="joint_upper_limit" value="1.657" />
	<xacro:property name="joint_effort" value="10000" />
	<xacro:property name="joint_velocity" value="100" />

	<link name="base_link" />

	<joint name="base_joint" type="fixed">
		<parent link="base_link" />
		<child link="body" />
		<origin xyz="0 0 0.1" rpy="0 0 0" />
	</joint>			

	<link name="body">
    		<visual>
      			<origin	xyz="0 0 0.016" rpy="0 0 0" />
      			<geometry>
				<mesh filename="package://taticoma_description/meshes/body.STL" scale="${dim_scale} ${dim_scale} ${dim_scale}" />
      			</geometry>
     			<material name="grey">
        			<color rgba="0.99 0.75 0.23 1" />
      			</material>
    		</visual>
	</link>

	<xacro:macro name="leg" params="side num x y angle">

  	<joint name="leg_center_joint_${side}${num}" type="fixed">
    		<origin xyz="${x} ${y} 0" rpy="0 0 0" /> 
    		<parent link="body" />
    		<child link="leg_center_${side}${num}" />
  	</joint>

    	<link name="leg_center_${side}${num}" />

	<joint name="coha_joint_${side}${num}" type="revolute">
    		<origin xyz="0 0 0" rpy="0 0 ${angle}" />
    		<parent link="leg_center_${side}${num}" />
    		<child link="coha_${side}${num}" />
    		<axis xyz="0 0 -1" />
    		<limit lower="${joint_lower_limit}" upper="${joint_upper_limit}" effort="${joint_effort}" velocity="${joint_velocity}" />
  	</joint>

  	<link name="coha_${side}${num}">
    		<visual>
      			<origin xyz="0 0 0" rpy="0 -${pi/2} 0" />
      			<geometry>
        			<mesh filename="package://taticoma_description/meshes/coha.STL" scale="${dim_scale} ${dim_scale} ${dim_scale}" />
      			</geometry>
      			<material name="">
        			<color rgba="0.74 0.11 0.22 1" />
      			</material>
    		</visual>
  	</link>

  	<joint name="femur_joint_${side}${num}" type="revolute">
    		<origin xyz="0.052 0 0" rpy="${pi/2} 0 0" />
    		<parent link="coha_${side}${num}" />
    		<child link="femur_${side}${num}" />
    		<axis xyz="0 0 -1" />
    		<limit lower="${joint_lower_limit}" upper="${joint_upper_limit}" effort="${joint_effort}" velocity="${joint_velocity}" />
  	</joint>

  	<link name="femur_${side}${num}">
    		<visual>
      			<origin xyz="0 0 0" rpy="0 0 ${pi/2}" />
      			<geometry>
        			<mesh filename="package://taticoma_description/meshes/femur.STL" scale="${dim_scale} ${dim_scale} ${dim_scale}"/>
      			</geometry>
      			<material name="">
        			<color rgba="0 0.7 0.7 1" />
      			</material>
    		</visual>
  	</link>

  	<joint name="tibia_joint_${side}${num}" type="revolute">

    		<origin xyz="0.0645 -0.0145 0" rpy="0 0 0" />
    		<parent link="femur_${side}${num}" />
    		<child link="tibia_${side}${num}" />
    		<axis xyz="0 0 1" />
    		<limit lower="${joint_lower_limit}" upper="${joint_upper_limit}" effort="${joint_effort}" velocity="${joint_velocity}" />
  	</joint>

  	<link name="tibia_${side}${num}">
    		<visual>
      			<origin xyz="0 0 0" rpy="0 0 ${pi/4}" />
      			<geometry>
       				<mesh filename="package://taticoma_description/meshes/tibia.STL" scale="${dim_scale} ${dim_scale} ${dim_scale}"/>
      			</geometry>
      			<material name="">
        			<color rgba="0.37 0.78 0.24 1" />
      			</material>
    		</visual>
  	</link>

  	<joint name="tibia_foot_joint_${side}${num}" type="fixed">
    		<origin xyz="-0.0059921  -0.12914 0" rpy="0 0 0" />
    		<parent link="tibia_${side}${num}" />
    		<child link="tibia_foot_${side}${num}" />
  	</joint>

  	<link name="tibia_foot_${side}${num}" />
	</xacro:macro>

	<xacro:leg side="r" num="1" x="0.060" 	y="0.120" 	angle="${pi/4}" />
	<xacro:leg side="r" num="2" x="0.1" 	y="0"		angle="0" />
	<xacro:leg side="r" num="3" x="0.060"	y="-0.120" 	angle="-${pi/4}" />

	<xacro:leg side="l" num="1" x="-0.060" 	y="0.120"	angle="${pi*3/4}" />
	<xacro:leg side="l" num="2" x="-0.1" 	y="0"		angle="-${pi}" />
	<xacro:leg side="l" num="3" x="-0.060" 	y="-0.120" 	angle="-${pi*3/4}" />


</robot>
